<?xml version="1.0" ?>

<sdf version="1.5">
  <!-- http://sdformat.org/spec?elem=sensor&ver=1.5 -->
  <model name="tankbot">
    <link name="chassis">
      <pose>0 0 0.135 0 0 0</pose>

      <inertial>
        <pose>0.0316 0 0  0 0 0</pose>
        <mass>2.0</mass>
        <inertia>
          <ixx>0.021459333333333334</ixx><iyy>0.021459333333333334</iyy><izz>0.03328533333333333</izz>
          <ixy>0</ixy><ixz>0</ixz><iyz>0</iyz>
        </inertia>
      </inertial>

      <collision name="collision">
        <geometry>
          <box>
            <size>0.316 0.316 0.17</size>
          </box>
        </geometry>
      </collision>

      <visual name="visual">
        <geometry>
          <box>
            <size>0.316 0.316 0.17</size>
          </box>
        </geometry>
        <material>
          <script>
            <uri>file://media/materials/scripts/gazebo.material</uri>
            <name>Gazebo/Yellow</name>
          </script>
        </material>
      </visual>
    </link>

    <link name="shoulder">
      <pose>
        0
        0.05
        0.135
        0 0 0
      </pose>

      <inertial>
        <mass>0.1</mass>
        <inertia>
          <ixx>0.0002925</ixx><iyy>0.0002925</iyy><izz>4.5e-05</izz>
          <ixy>0</ixy><ixz>0</ixz><iyz>0</iyz>
        </inertia>
      </inertial>

      <visual name='visual'>
        <geometry><cylinder><radius>0.03</radius><length>0.18</length></cylinder></geometry>
        <material>
          <script><uri>file://media/materials/scripts/gazebo.material</uri><name>Gazebo/Blue</name></script>
        </material>
      </visual>

      <collision name='collision'>
        <geometry><cylinder><radius>0.03</radius><length>0.18</length></cylinder></geometry>
      </collision>
    </link>

    

    <link name="right_blocker">
      <pose>
        -0.28670321550114714
        -0.15075175272286612
        0.135
        0 0 0.6108652381980153
      </pose>

      <inertial>
        <mass>0.1</mass>
        <inertia>
          <ixx>4.166666666666667e-05</ixx><iyy>0.004104166666666666</iyy><izz>0.004104166666666666</izz>
          <ixy>0</ixy><ixz>0</ixz><iyz>0</iyz>
        </inertia>
      </inertial>

      <visual name='visual'>
        <geometry><box><size>0.7 0.05 0.05</size></box></geometry>
        <material>
          <script><uri>file://media/materials/scripts/gazebo.material</uri><name>Gazebo/Black</name></script>
        </material>
      </visual>

      <collision name='collision'>
        <geometry><box><size>0.7 0.05 0.05</size></box></geometry>
      </collision>
    </link>

    <joint name="right_blocker_joint" type="fixed">
      <parent>shoulder</parent>
      <child>right_blocker</child>
    </joint>

    

    <link name="left_blocker">
      <pose>
        0.28670321550114714
        -0.15075175272286612
        0.135
        0 0 2.5307274153917776
      </pose>

      <inertial>
        <mass>0.1</mass>
        <inertia>
          <ixx>4.166666666666667e-05</ixx><iyy>0.004104166666666666</iyy><izz>0.004104166666666666</izz>
          <ixy>0</ixy><ixz>0</ixz><iyz>0</iyz>
        </inertia>
      </inertial>

      <visual name='visual'>
        <geometry><box><size>0.7 0.05 0.05</size></box></geometry>
        <material>
          <script><uri>file://media/materials/scripts/gazebo.material</uri><name>Gazebo/Black</name></script>
        </material>
      </visual>

      <collision name='collision'>
        <geometry><box><size>0.7 0.05 0.05</size></box></geometry>
      </collision>
    </link>

    <joint name="left_blocker_joint" type="fixed">
      <parent>shoulder</parent>
      <child>left_blocker</child>
    </joint>

    

    <joint name="left_shoulder_joint" type="revolute">
      <parent>chassis</parent>
      <child>shoulder</child>
      <axis>
        <xyz>0 0 1</xyz>
      </axis>
    </joint>




    
    <link name="wheel_fl">
      <pose>
        0.0948 0.192 0.05
        -1.5707963267948966 -0.08726646259971647 0
      </pose>
      <inertial>
        <mass>0.25</mass>
        <inertia>
          <ixx>0.00018958333333333338</ixx>
          <iyy>0.00018958333333333338</iyy>
          <izz>0.00031250000000000006</izz>
          <ixy>0</ixy>
          <ixz>0</ixz>
          <iyz>0</iyz>
        </inertia>
      </inertial>
      <collision name="collision">
        <geometry>
          <cylinder>
            <radius>0.05</radius>
            <length>0.04</length>
          </cylinder>
        </geometry>
      </collision>
      <visual name="visual">
        <geometry>
          <cylinder>
            <radius>0.05</radius>
            <length>0.04</length>
          </cylinder>
        </geometry>
        <material>
          <script>
            <uri>file://media/materials/scripts/gazebo.material</uri>
            <name>Gazebo/Black</name>
          </script>
        </material>
      </visual>
    </link>
    
    <joint name="wheel_fl_drive" type="revolute">
      <parent>chassis</parent>
      <child>wheel_fl</child>
      <axis>
        <xyz>0 0 1</xyz>
      </axis>
    </joint>
    
    <link name="wheel_fr">
      <pose>
        0.0948 -0.192 0.05
        -1.5707963267948966 -0.08726646259971647 0
      </pose>
      <inertial>
        <mass>0.25</mass>
        <inertia>
          <ixx>0.00018958333333333338</ixx>
          <iyy>0.00018958333333333338</iyy>
          <izz>0.00031250000000000006</izz>
          <ixy>0</ixy>
          <ixz>0</ixz>
          <iyz>0</iyz>
        </inertia>
      </inertial>
      <collision name="collision">
        <geometry>
          <cylinder>
            <radius>0.05</radius>
            <length>0.04</length>
          </cylinder>
        </geometry>
      </collision>
      <visual name="visual">
        <geometry>
          <cylinder>
            <radius>0.05</radius>
            <length>0.04</length>
          </cylinder>
        </geometry>
        <material>
          <script>
            <uri>file://media/materials/scripts/gazebo.material</uri>
            <name>Gazebo/Black</name>
          </script>
        </material>
      </visual>
    </link>
    
    <joint name="wheel_fr_drive" type="revolute">
      <parent>chassis</parent>
      <child>wheel_fr</child>
      <axis>
        <xyz>0 0 1</xyz>
      </axis>
    </joint>
    
    
    <link name="wheel_rl">
      <pose>
       -0.0948 0.192 0.05
       -1.5707963267948966 0 0
      </pose>
      <inertial>
        <mass>0.25</mass>
        <inertia>
          <ixx>0.00018958333333333338</ixx>
          <iyy>0.00018958333333333338</iyy>
          <izz>0.00031250000000000006</izz>
          <ixy>0</ixy>
          <ixz>0</ixz>
          <iyz>0</iyz>
        </inertia>
      </inertial>
      <collision name="collision">
        <geometry>
          <cylinder>
            <radius>0.05</radius>
            <length>0.04</length>
          </cylinder>
        </geometry>
      </collision>
      <visual name="visual">
        <geometry>
          <cylinder>
            <radius>0.05</radius>
            <length>0.04</length>
          </cylinder>
        </geometry>
        <material>
          <script>
            <uri>file://media/materials/scripts/gazebo.material</uri>
            <name>Gazebo/Black</name>
          </script>
        </material>
      </visual>
    </link>
    <joint name="wheel_rl_drive" type="revolute">
      <parent>chassis</parent>
      <child>wheel_rl</child>
      <axis>
        <xyz>0 0 1</xyz>
      </axis>
    </joint>
    
    <link name="wheel_rr">
      <pose>
       -0.0948 -0.192 0.05
       -1.5707963267948966 0 0
      </pose>
      <inertial>
        <mass>0.25</mass>
        <inertia>
          <ixx>0.00018958333333333338</ixx>
          <iyy>0.00018958333333333338</iyy>
          <izz>0.00031250000000000006</izz>
          <ixy>0</ixy>
          <ixz>0</ixz>
          <iyz>0</iyz>
        </inertia>
      </inertial>
      <collision name="collision">
        <geometry>
          <cylinder>
            <radius>0.05</radius>
            <length>0.04</length>
          </cylinder>
        </geometry>
      </collision>
      <visual name="visual">
        <geometry>
          <cylinder>
            <radius>0.05</radius>
            <length>0.04</length>
          </cylinder>
        </geometry>
        <material>
          <script>
            <uri>file://media/materials/scripts/gazebo.material</uri>
            <name>Gazebo/Black</name>
          </script>
        </material>
      </visual>
    </link>
    <joint name="wheel_rr_drive" type="revolute">
      <parent>chassis</parent>
      <child>wheel_rr</child>
      <axis>
        <xyz>0 0 1</xyz>
      </axis>
    </joint>
    

    <include>
      <uri>model://ultrasonic_sensor</uri>
      <pose>
        0.0 0.0 0.22000000000000003
        0.0 0.0 1.5707963267948966
      </pose>
    </include>

    <joint name="sonar_joint" type="fixed">
      <child>ultrasonic_sensor::link</child>
      <parent>chassis</parent>
    </joint>

    <include>
      <uri>model://camera_sensor</uri>
      <pose>
        0.0 0.0 0.3
        0.0 0.0 1.5707963267948966
      </pose>
    </include>

    <joint name="camera_joint" type="fixed">
      <child>camera_sensor::link</child>
      <parent>chassis</parent>
    </joint>
  </model>
</sdf>
